{
 "cells": [
  {
   "cell_type": "code",
   "execution_count": 1,
   "metadata": {},
   "outputs": [
    {
     "name": "stdout",
     "output_type": "stream",
     "text": [
      "Rafael is nice\n"
     ]
    }
   ],
   "source": [
    "print(\"Rafael is nice\")"
   ]
  },
  {
   "cell_type": "code",
   "execution_count": null,
   "metadata": {},
   "outputs": [
    {
     "name": "stderr",
     "output_type": "stream",
     "text": [
      "ERROR:root:Internal Python error in the inspect module.\n",
      "Below is the traceback from this internal error.\n",
      "\n",
      "ERROR:root:Internal Python error in the inspect module.\n",
      "Below is the traceback from this internal error.\n",
      "\n",
      "ERROR:root:Internal Python error in the inspect module.\n",
      "Below is the traceback from this internal error.\n",
      "\n"
     ]
    },
    {
     "name": "stdout",
     "output_type": "stream",
     "text": [
      "Traceback (most recent call last):\n",
      "  File \"/Users/gabrielvictorgomesferreira/opt/anaconda3/lib/python3.8/site-packages/IPython/core/interactiveshell.py\", line 3343, in run_code\n",
      "    exec(code_obj, self.user_global_ns, self.user_ns)\n",
      "  File \"<ipython-input-2-b3c54a058618>\", line 10, in <module>\n",
      "    import matplotlib.pyplot as plt\n",
      "  File \"/Users/gabrielvictorgomesferreira/opt/anaconda3/lib/python3.8/site-packages/matplotlib/__init__.py\", line 1015, in <module>\n",
      "    rcParams = rc_params()\n",
      "  File \"/Users/gabrielvictorgomesferreira/opt/anaconda3/lib/python3.8/site-packages/matplotlib/__init__.py\", line 878, in rc_params\n",
      "    return rc_params_from_file(matplotlib_fname(), fail_on_error)\n",
      "  File \"/Users/gabrielvictorgomesferreira/opt/anaconda3/lib/python3.8/site-packages/matplotlib/__init__.py\", line 731, in matplotlib_fname\n",
      "    for fname in gen_candidates():\n",
      "  File \"/Users/gabrielvictorgomesferreira/opt/anaconda3/lib/python3.8/site-packages/matplotlib/__init__.py\", line 720, in gen_candidates\n",
      "    yield os.path.join(os.getcwd(), 'matplotlibrc')\n",
      "FileNotFoundError: [Errno 2] No such file or directory\n",
      "\n",
      "During handling of the above exception, another exception occurred:\n",
      "\n",
      "Traceback (most recent call last):\n",
      "  File \"/Users/gabrielvictorgomesferreira/opt/anaconda3/lib/python3.8/site-packages/IPython/core/interactiveshell.py\", line 2044, in showtraceback\n",
      "    stb = value._render_traceback_()\n",
      "AttributeError: 'FileNotFoundError' object has no attribute '_render_traceback_'\n",
      "\n",
      "During handling of the above exception, another exception occurred:\n",
      "\n",
      "Traceback (most recent call last):\n",
      "  File \"/Users/gabrielvictorgomesferreira/opt/anaconda3/lib/python3.8/site-packages/IPython/core/ultratb.py\", line 1169, in get_records\n",
      "    return _fixed_getinnerframes(etb, number_of_lines_of_context, tb_offset)\n",
      "  File \"/Users/gabrielvictorgomesferreira/opt/anaconda3/lib/python3.8/site-packages/IPython/core/ultratb.py\", line 316, in wrapped\n",
      "    return f(*args, **kwargs)\n",
      "  File \"/Users/gabrielvictorgomesferreira/opt/anaconda3/lib/python3.8/site-packages/IPython/core/ultratb.py\", line 350, in _fixed_getinnerframes\n",
      "    records = fix_frame_records_filenames(inspect.getinnerframes(etb, context))\n",
      "  File \"/Users/gabrielvictorgomesferreira/opt/anaconda3/lib/python3.8/inspect.py\", line 1503, in getinnerframes\n",
      "    frameinfo = (tb.tb_frame,) + getframeinfo(tb, context)\n",
      "  File \"/Users/gabrielvictorgomesferreira/opt/anaconda3/lib/python3.8/inspect.py\", line 1461, in getframeinfo\n",
      "    filename = getsourcefile(frame) or getfile(frame)\n",
      "  File \"/Users/gabrielvictorgomesferreira/opt/anaconda3/lib/python3.8/inspect.py\", line 708, in getsourcefile\n",
      "    if getattr(getmodule(object, filename), '__loader__', None) is not None:\n",
      "  File \"/Users/gabrielvictorgomesferreira/opt/anaconda3/lib/python3.8/inspect.py\", line 737, in getmodule\n",
      "    file = getabsfile(object, _filename)\n",
      "  File \"/Users/gabrielvictorgomesferreira/opt/anaconda3/lib/python3.8/inspect.py\", line 721, in getabsfile\n",
      "    return os.path.normcase(os.path.abspath(_filename))\n",
      "  File \"/Users/gabrielvictorgomesferreira/opt/anaconda3/lib/python3.8/posixpath.py\", line 379, in abspath\n",
      "    cwd = os.getcwd()\n",
      "FileNotFoundError: [Errno 2] No such file or directory\n",
      "Traceback (most recent call last):\n",
      "  File \"/Users/gabrielvictorgomesferreira/opt/anaconda3/lib/python3.8/site-packages/IPython/core/interactiveshell.py\", line 3343, in run_code\n",
      "    exec(code_obj, self.user_global_ns, self.user_ns)\n",
      "  File \"<ipython-input-2-b3c54a058618>\", line 10, in <module>\n",
      "    import matplotlib.pyplot as plt\n",
      "  File \"/Users/gabrielvictorgomesferreira/opt/anaconda3/lib/python3.8/site-packages/matplotlib/__init__.py\", line 1015, in <module>\n",
      "    rcParams = rc_params()\n",
      "  File \"/Users/gabrielvictorgomesferreira/opt/anaconda3/lib/python3.8/site-packages/matplotlib/__init__.py\", line 878, in rc_params\n",
      "    return rc_params_from_file(matplotlib_fname(), fail_on_error)\n",
      "  File \"/Users/gabrielvictorgomesferreira/opt/anaconda3/lib/python3.8/site-packages/matplotlib/__init__.py\", line 731, in matplotlib_fname\n",
      "    for fname in gen_candidates():\n",
      "  File \"/Users/gabrielvictorgomesferreira/opt/anaconda3/lib/python3.8/site-packages/matplotlib/__init__.py\", line 720, in gen_candidates\n",
      "    yield os.path.join(os.getcwd(), 'matplotlibrc')\n",
      "FileNotFoundError: [Errno 2] No such file or directory\n",
      "\n",
      "During handling of the above exception, another exception occurred:\n",
      "\n",
      "Traceback (most recent call last):\n",
      "  File \"/Users/gabrielvictorgomesferreira/opt/anaconda3/lib/python3.8/site-packages/IPython/core/interactiveshell.py\", line 2044, in showtraceback\n",
      "    stb = value._render_traceback_()\n",
      "AttributeError: 'FileNotFoundError' object has no attribute '_render_traceback_'\n",
      "\n",
      "During handling of the above exception, another exception occurred:\n",
      "\n",
      "Traceback (most recent call last):\n",
      "  File \"/Users/gabrielvictorgomesferreira/opt/anaconda3/lib/python3.8/site-packages/IPython/core/interactiveshell.py\", line 3263, in run_ast_nodes\n",
      "    if (await self.run_code(code, result,  async_=asy)):\n",
      "  File \"/Users/gabrielvictorgomesferreira/opt/anaconda3/lib/python3.8/site-packages/IPython/core/interactiveshell.py\", line 3360, in run_code\n",
      "    self.showtraceback(running_compiled_code=True)\n",
      "  File \"/Users/gabrielvictorgomesferreira/opt/anaconda3/lib/python3.8/site-packages/IPython/core/interactiveshell.py\", line 2046, in showtraceback\n",
      "    stb = self.InteractiveTB.structured_traceback(etype,\n",
      "  File \"/Users/gabrielvictorgomesferreira/opt/anaconda3/lib/python3.8/site-packages/IPython/core/ultratb.py\", line 1435, in structured_traceback\n",
      "    return FormattedTB.structured_traceback(\n",
      "  File \"/Users/gabrielvictorgomesferreira/opt/anaconda3/lib/python3.8/site-packages/IPython/core/ultratb.py\", line 1335, in structured_traceback\n",
      "    return VerboseTB.structured_traceback(\n",
      "  File \"/Users/gabrielvictorgomesferreira/opt/anaconda3/lib/python3.8/site-packages/IPython/core/ultratb.py\", line 1192, in structured_traceback\n",
      "    formatted_exception = self.format_exception_as_a_whole(etype, evalue, etb, number_of_lines_of_context,\n",
      "  File \"/Users/gabrielvictorgomesferreira/opt/anaconda3/lib/python3.8/site-packages/IPython/core/ultratb.py\", line 1150, in format_exception_as_a_whole\n",
      "    last_unique, recursion_repeat = find_recursion(orig_etype, evalue, records)\n",
      "  File \"/Users/gabrielvictorgomesferreira/opt/anaconda3/lib/python3.8/site-packages/IPython/core/ultratb.py\", line 451, in find_recursion\n",
      "    return len(records), 0\n",
      "TypeError: object of type 'NoneType' has no len()\n",
      "\n",
      "During handling of the above exception, another exception occurred:\n",
      "\n",
      "Traceback (most recent call last):\n",
      "  File \"/Users/gabrielvictorgomesferreira/opt/anaconda3/lib/python3.8/site-packages/IPython/core/interactiveshell.py\", line 2044, in showtraceback\n",
      "    stb = value._render_traceback_()\n",
      "AttributeError: 'TypeError' object has no attribute '_render_traceback_'\n",
      "\n",
      "During handling of the above exception, another exception occurred:\n",
      "\n",
      "Traceback (most recent call last):\n",
      "  File \"/Users/gabrielvictorgomesferreira/opt/anaconda3/lib/python3.8/site-packages/IPython/core/ultratb.py\", line 1169, in get_records\n",
      "    return _fixed_getinnerframes(etb, number_of_lines_of_context, tb_offset)\n",
      "  File \"/Users/gabrielvictorgomesferreira/opt/anaconda3/lib/python3.8/site-packages/IPython/core/ultratb.py\", line 316, in wrapped\n",
      "    return f(*args, **kwargs)\n",
      "  File \"/Users/gabrielvictorgomesferreira/opt/anaconda3/lib/python3.8/site-packages/IPython/core/ultratb.py\", line 350, in _fixed_getinnerframes\n",
      "    records = fix_frame_records_filenames(inspect.getinnerframes(etb, context))\n",
      "  File \"/Users/gabrielvictorgomesferreira/opt/anaconda3/lib/python3.8/inspect.py\", line 1503, in getinnerframes\n",
      "    frameinfo = (tb.tb_frame,) + getframeinfo(tb, context)\n",
      "  File \"/Users/gabrielvictorgomesferreira/opt/anaconda3/lib/python3.8/inspect.py\", line 1461, in getframeinfo\n",
      "    filename = getsourcefile(frame) or getfile(frame)\n",
      "  File \"/Users/gabrielvictorgomesferreira/opt/anaconda3/lib/python3.8/inspect.py\", line 708, in getsourcefile\n",
      "    if getattr(getmodule(object, filename), '__loader__', None) is not None:\n",
      "  File \"/Users/gabrielvictorgomesferreira/opt/anaconda3/lib/python3.8/inspect.py\", line 737, in getmodule\n",
      "    file = getabsfile(object, _filename)\n",
      "  File \"/Users/gabrielvictorgomesferreira/opt/anaconda3/lib/python3.8/inspect.py\", line 721, in getabsfile\n",
      "    return os.path.normcase(os.path.abspath(_filename))\n",
      "  File \"/Users/gabrielvictorgomesferreira/opt/anaconda3/lib/python3.8/posixpath.py\", line 379, in abspath\n",
      "    cwd = os.getcwd()\n",
      "FileNotFoundError: [Errno 2] No such file or directory\n",
      "Traceback (most recent call last):\n",
      "  File \"/Users/gabrielvictorgomesferreira/opt/anaconda3/lib/python3.8/site-packages/IPython/core/interactiveshell.py\", line 3343, in run_code\n",
      "    exec(code_obj, self.user_global_ns, self.user_ns)\n",
      "  File \"<ipython-input-2-b3c54a058618>\", line 10, in <module>\n",
      "    import matplotlib.pyplot as plt\n",
      "  File \"/Users/gabrielvictorgomesferreira/opt/anaconda3/lib/python3.8/site-packages/matplotlib/__init__.py\", line 1015, in <module>\n",
      "    rcParams = rc_params()\n",
      "  File \"/Users/gabrielvictorgomesferreira/opt/anaconda3/lib/python3.8/site-packages/matplotlib/__init__.py\", line 878, in rc_params\n",
      "    return rc_params_from_file(matplotlib_fname(), fail_on_error)\n",
      "  File \"/Users/gabrielvictorgomesferreira/opt/anaconda3/lib/python3.8/site-packages/matplotlib/__init__.py\", line 731, in matplotlib_fname\n",
      "    for fname in gen_candidates():\n",
      "  File \"/Users/gabrielvictorgomesferreira/opt/anaconda3/lib/python3.8/site-packages/matplotlib/__init__.py\", line 720, in gen_candidates\n",
      "    yield os.path.join(os.getcwd(), 'matplotlibrc')\n",
      "FileNotFoundError: [Errno 2] No such file or directory\n",
      "\n",
      "During handling of the above exception, another exception occurred:\n",
      "\n",
      "Traceback (most recent call last):\n",
      "  File \"/Users/gabrielvictorgomesferreira/opt/anaconda3/lib/python3.8/site-packages/IPython/core/interactiveshell.py\", line 2044, in showtraceback\n",
      "    stb = value._render_traceback_()\n",
      "AttributeError: 'FileNotFoundError' object has no attribute '_render_traceback_'\n",
      "\n",
      "During handling of the above exception, another exception occurred:\n",
      "\n",
      "Traceback (most recent call last):\n",
      "  File \"/Users/gabrielvictorgomesferreira/opt/anaconda3/lib/python3.8/site-packages/IPython/core/interactiveshell.py\", line 3263, in run_ast_nodes\n",
      "    if (await self.run_code(code, result,  async_=asy)):\n",
      "  File \"/Users/gabrielvictorgomesferreira/opt/anaconda3/lib/python3.8/site-packages/IPython/core/interactiveshell.py\", line 3360, in run_code\n",
      "    self.showtraceback(running_compiled_code=True)\n",
      "  File \"/Users/gabrielvictorgomesferreira/opt/anaconda3/lib/python3.8/site-packages/IPython/core/interactiveshell.py\", line 2046, in showtraceback\n",
      "    stb = self.InteractiveTB.structured_traceback(etype,\n",
      "  File \"/Users/gabrielvictorgomesferreira/opt/anaconda3/lib/python3.8/site-packages/IPython/core/ultratb.py\", line 1435, in structured_traceback\n",
      "    return FormattedTB.structured_traceback(\n",
      "  File \"/Users/gabrielvictorgomesferreira/opt/anaconda3/lib/python3.8/site-packages/IPython/core/ultratb.py\", line 1335, in structured_traceback\n",
      "    return VerboseTB.structured_traceback(\n",
      "  File \"/Users/gabrielvictorgomesferreira/opt/anaconda3/lib/python3.8/site-packages/IPython/core/ultratb.py\", line 1192, in structured_traceback\n",
      "    formatted_exception = self.format_exception_as_a_whole(etype, evalue, etb, number_of_lines_of_context,\n",
      "  File \"/Users/gabrielvictorgomesferreira/opt/anaconda3/lib/python3.8/site-packages/IPython/core/ultratb.py\", line 1150, in format_exception_as_a_whole\n",
      "    last_unique, recursion_repeat = find_recursion(orig_etype, evalue, records)\n",
      "  File \"/Users/gabrielvictorgomesferreira/opt/anaconda3/lib/python3.8/site-packages/IPython/core/ultratb.py\", line 451, in find_recursion\n",
      "    return len(records), 0\n",
      "TypeError: object of type 'NoneType' has no len()\n",
      "\n",
      "During handling of the above exception, another exception occurred:\n",
      "\n",
      "Traceback (most recent call last):\n",
      "  File \"/Users/gabrielvictorgomesferreira/opt/anaconda3/lib/python3.8/site-packages/IPython/core/interactiveshell.py\", line 2044, in showtraceback\n",
      "    stb = value._render_traceback_()\n",
      "AttributeError: 'TypeError' object has no attribute '_render_traceback_'\n",
      "\n",
      "During handling of the above exception, another exception occurred:\n",
      "\n",
      "Traceback (most recent call last):\n",
      "  File \"/Users/gabrielvictorgomesferreira/opt/anaconda3/lib/python3.8/site-packages/IPython/core/interactiveshell.py\", line 2895, in _run_cell\n",
      "    return runner(coro)\n",
      "  File \"/Users/gabrielvictorgomesferreira/opt/anaconda3/lib/python3.8/site-packages/IPython/core/async_helpers.py\", line 68, in _pseudo_sync_runner\n",
      "    coro.send(None)\n",
      "  File \"/Users/gabrielvictorgomesferreira/opt/anaconda3/lib/python3.8/site-packages/IPython/core/interactiveshell.py\", line 3071, in run_cell_async\n",
      "    has_raised = await self.run_ast_nodes(code_ast.body, cell_name,\n",
      "  File \"/Users/gabrielvictorgomesferreira/opt/anaconda3/lib/python3.8/site-packages/IPython/core/interactiveshell.py\", line 3282, in run_ast_nodes\n",
      "    self.showtraceback()\n",
      "  File \"/Users/gabrielvictorgomesferreira/opt/anaconda3/lib/python3.8/site-packages/IPython/core/interactiveshell.py\", line 2046, in showtraceback\n",
      "    stb = self.InteractiveTB.structured_traceback(etype,\n",
      "  File \"/Users/gabrielvictorgomesferreira/opt/anaconda3/lib/python3.8/site-packages/IPython/core/ultratb.py\", line 1435, in structured_traceback\n",
      "    return FormattedTB.structured_traceback(\n",
      "  File \"/Users/gabrielvictorgomesferreira/opt/anaconda3/lib/python3.8/site-packages/IPython/core/ultratb.py\", line 1335, in structured_traceback\n",
      "    return VerboseTB.structured_traceback(\n",
      "  File \"/Users/gabrielvictorgomesferreira/opt/anaconda3/lib/python3.8/site-packages/IPython/core/ultratb.py\", line 1210, in structured_traceback\n",
      "    formatted_exceptions += self.format_exception_as_a_whole(etype, evalue, etb, lines_of_context,\n",
      "  File \"/Users/gabrielvictorgomesferreira/opt/anaconda3/lib/python3.8/site-packages/IPython/core/ultratb.py\", line 1150, in format_exception_as_a_whole\n",
      "    last_unique, recursion_repeat = find_recursion(orig_etype, evalue, records)\n",
      "  File \"/Users/gabrielvictorgomesferreira/opt/anaconda3/lib/python3.8/site-packages/IPython/core/ultratb.py\", line 451, in find_recursion\n",
      "    return len(records), 0\n",
      "TypeError: object of type 'NoneType' has no len()\n",
      "\n",
      "During handling of the above exception, another exception occurred:\n",
      "\n",
      "Traceback (most recent call last):\n",
      "  File \"/Users/gabrielvictorgomesferreira/opt/anaconda3/lib/python3.8/site-packages/IPython/core/interactiveshell.py\", line 2044, in showtraceback\n",
      "    stb = value._render_traceback_()\n",
      "AttributeError: 'TypeError' object has no attribute '_render_traceback_'\n",
      "\n",
      "During handling of the above exception, another exception occurred:\n",
      "\n",
      "Traceback (most recent call last):\n",
      "  File \"/Users/gabrielvictorgomesferreira/opt/anaconda3/lib/python3.8/site-packages/IPython/core/ultratb.py\", line 1169, in get_records\n",
      "    return _fixed_getinnerframes(etb, number_of_lines_of_context, tb_offset)\n",
      "  File \"/Users/gabrielvictorgomesferreira/opt/anaconda3/lib/python3.8/site-packages/IPython/core/ultratb.py\", line 316, in wrapped\n",
      "    return f(*args, **kwargs)\n",
      "  File \"/Users/gabrielvictorgomesferreira/opt/anaconda3/lib/python3.8/site-packages/IPython/core/ultratb.py\", line 350, in _fixed_getinnerframes\n",
      "    records = fix_frame_records_filenames(inspect.getinnerframes(etb, context))\n",
      "  File \"/Users/gabrielvictorgomesferreira/opt/anaconda3/lib/python3.8/inspect.py\", line 1503, in getinnerframes\n",
      "    frameinfo = (tb.tb_frame,) + getframeinfo(tb, context)\n",
      "  File \"/Users/gabrielvictorgomesferreira/opt/anaconda3/lib/python3.8/inspect.py\", line 1461, in getframeinfo\n",
      "    filename = getsourcefile(frame) or getfile(frame)\n",
      "  File \"/Users/gabrielvictorgomesferreira/opt/anaconda3/lib/python3.8/inspect.py\", line 708, in getsourcefile\n",
      "    if getattr(getmodule(object, filename), '__loader__', None) is not None:\n",
      "  File \"/Users/gabrielvictorgomesferreira/opt/anaconda3/lib/python3.8/inspect.py\", line 737, in getmodule\n",
      "    file = getabsfile(object, _filename)\n",
      "  File \"/Users/gabrielvictorgomesferreira/opt/anaconda3/lib/python3.8/inspect.py\", line 721, in getabsfile\n",
      "    return os.path.normcase(os.path.abspath(_filename))\n",
      "  File \"/Users/gabrielvictorgomesferreira/opt/anaconda3/lib/python3.8/posixpath.py\", line 379, in abspath\n",
      "    cwd = os.getcwd()\n",
      "FileNotFoundError: [Errno 2] No such file or directory\n"
     ]
    }
   ],
   "source": [
    "#for data\n",
    "import numpy as np\n",
    "import pandas as pd\n",
    "from pandas import Series,DataFrame\n",
    "\n",
    "#math\n",
    "import math\n",
    "\n",
    "#plot\n",
    "import matplotlib.pyplot as plt\n",
    "import seaborn as sns\n",
    "sns.set_style('whitegrid')\n",
    "%matplotlib inline\n",
    "\n",
    "#machine learning \n",
    "import sklearn \n",
    "from sklearn.linear_model import LinearRegression\n",
    "from sklearn.model_selection import train_test_split\n",
    "from sklearn.metrics import mean_squared_error"
   ]
  },
  {
   "cell_type": "code",
   "execution_count": null,
   "metadata": {},
   "outputs": [],
   "source": []
  }
 ],
 "metadata": {
  "kernelspec": {
   "display_name": "Python 3",
   "language": "python",
   "name": "python3"
  },
  "language_info": {
   "codemirror_mode": {
    "name": "ipython",
    "version": 3
   },
   "file_extension": ".py",
   "mimetype": "text/x-python",
   "name": "python",
   "nbconvert_exporter": "python",
   "pygments_lexer": "ipython3",
   "version": "3.8.3"
  }
 },
 "nbformat": 4,
 "nbformat_minor": 4
}
